2024-06-23 21:16:12,908 INFO Code Start...
2024-06-23 21:16:12,908 INFO Config Loaded Successfully!
2024-06-23 21:16:12,908 INFO Training Start...
2024-06-23 21:16:12,941 INFO Using device cuda
2024-06-23 21:16:12,941 INFO Make Model Folder Called Weights
2024-06-23 21:16:12,942 INFO Dataset load Starting ...
2024-06-23 21:17:23,632 INFO Loaded IIT Bombay English-Hindi Dataset Successfully!
2024-06-23 21:17:23,633 INFO Create Tokenizer File path Successfully!
2024-06-23 21:17:23,652 INFO Create Tokenizer File path Successfully!
2024-06-23 21:17:23,665 INFO Source and Target Tokenizer Built Successfully!
2024-06-23 21:17:23,741 INFO Splitting dataset Successfully!
2024-06-23 21:17:23,741 INFO Preprocessing with Bilingual Dataset Starting ... 
2024-06-23 21:17:23,745 INFO Preprocessing with Bilingual Dataset Successfully!
2024-06-23 21:17:23,753 ERROR An error occurred
Traceback (most recent call last):
  File "D:\Langauge Translation Transformer\Language_Translation_Transformer_With_Modular_Coding\main.py", line 20, in <module>
    train_model(config)  # Training model with the config arguments
  File "D:\Langauge Translation Transformer\Language_Translation_Transformer_With_Modular_Coding\train.py", line 31, in train_model
    train_dataloader, val_dataloader, tokenizer_src, tokenizer_tgt = get_ds(config)
  File "D:\Langauge Translation Transformer\Language_Translation_Transformer_With_Modular_Coding\getdata\get_ds.py", line 41, in get_ds
    tgt_ids = tokenizer_tgt.encode(pair['translation'][config['lang_tgt']]).ids
KeyError: 'it'
2024-06-23 21:49:50,104 INFO Code Start...
2024-06-23 21:49:50,104 INFO Config Loaded Successfully!
2024-06-23 21:49:50,105 INFO Training Start...
2024-06-23 21:49:50,131 INFO Using device cuda
2024-06-23 21:49:50,131 INFO Make Model Folder Called Weights
2024-06-23 21:49:50,132 INFO Dataset load Starting ...
2024-06-23 21:50:08,377 ERROR An error occurred
Traceback (most recent call last):
  File "D:\Langauge Translation Transformer\Language_Translation_Transformer_With_Modular_Coding\main.py", line 20, in <module>
    train_model(config)  # Training model with the config arguments
  File "D:\Langauge Translation Transformer\Language_Translation_Transformer_With_Modular_Coding\train.py", line 31, in train_model
    train_dataloader, val_dataloader, tokenizer_src, tokenizer_tgt = get_ds(config)
  File "D:\Langauge Translation Transformer\Language_Translation_Transformer_With_Modular_Coding\getdata\get_ds.py", line 16, in get_ds
    ds_raw = load_dataset('wmt16', 'en-hi', split='train[:10%]')  # Adjust split if needed
  File "C:\Users\Danjin\anaconda3\envs\python10\lib\site-packages\datasets\load.py", line 2594, in load_dataset
    builder_instance = load_dataset_builder(
  File "C:\Users\Danjin\anaconda3\envs\python10\lib\site-packages\datasets\load.py", line 2303, in load_dataset_builder
    builder_instance: DatasetBuilder = builder_cls(
  File "C:\Users\Danjin\anaconda3\envs\python10\lib\site-packages\datasets\builder.py", line 374, in __init__
    self.config, self.config_id = self._create_builder_config(
  File "C:\Users\Danjin\anaconda3\envs\python10\lib\site-packages\datasets\builder.py", line 601, in _create_builder_config
    raise ValueError(
ValueError: BuilderConfig 'en-hi' not found. Available: ['cs-en', 'de-en', 'fi-en', 'ro-en', 'ru-en', 'tr-en']
2024-06-23 21:51:04,716 INFO Code Start...
2024-06-23 21:51:04,717 INFO Config Loaded Successfully!
2024-06-23 21:51:04,717 INFO Training Start...
2024-06-23 21:51:04,742 INFO Using device cuda
2024-06-23 21:51:04,742 INFO Make Model Folder Called Weights
2024-06-23 21:51:04,742 INFO Dataset load Starting ...
2024-06-23 21:51:04,742 ERROR An error occurred
Traceback (most recent call last):
  File "D:\Langauge Translation Transformer\Language_Translation_Transformer_With_Modular_Coding\main.py", line 20, in <module>
    train_model(config)  # Training model with the config arguments
  File "D:\Langauge Translation Transformer\Language_Translation_Transformer_With_Modular_Coding\train.py", line 31, in train_model
    train_dataloader, val_dataloader, tokenizer_src, tokenizer_tgt = get_ds(config)
  File "D:\Langauge Translation Transformer\Language_Translation_Transformer_With_Modular_Coding\getdata\get_ds.py", line 16, in get_ds
    ds_raw = load_dataset('opus', 'opus', name='opus_books', split='train[:10%]', language_pair=('en', 'hi'))
TypeError: load_dataset() got multiple values for argument 'name'
2024-06-23 21:51:39,737 INFO Code Start...
2024-06-23 21:51:39,738 INFO Config Loaded Successfully!
2024-06-23 21:51:39,738 INFO Training Start...
2024-06-23 21:51:39,761 INFO Using device cuda
2024-06-23 21:51:39,761 INFO Make Model Folder Called Weights
2024-06-23 21:51:39,761 INFO Dataset load Starting ...
2024-06-23 21:51:40,536 ERROR An error occurred
Traceback (most recent call last):
  File "D:\Langauge Translation Transformer\Language_Translation_Transformer_With_Modular_Coding\main.py", line 20, in <module>
    train_model(config)  # Training model with the config arguments
  File "D:\Langauge Translation Transformer\Language_Translation_Transformer_With_Modular_Coding\train.py", line 31, in train_model
    train_dataloader, val_dataloader, tokenizer_src, tokenizer_tgt = get_ds(config)
  File "D:\Langauge Translation Transformer\Language_Translation_Transformer_With_Modular_Coding\getdata\get_ds.py", line 16, in get_ds
    ds_raw = load_dataset('opus', name='opus_books', split='train[:10%]', language_pair=('en', 'hi'))
  File "C:\Users\Danjin\anaconda3\envs\python10\lib\site-packages\datasets\load.py", line 2594, in load_dataset
    builder_instance = load_dataset_builder(
  File "C:\Users\Danjin\anaconda3\envs\python10\lib\site-packages\datasets\load.py", line 2266, in load_dataset_builder
    dataset_module = dataset_module_factory(
  File "C:\Users\Danjin\anaconda3\envs\python10\lib\site-packages\datasets\load.py", line 1908, in dataset_module_factory
    raise e1 from None
  File "C:\Users\Danjin\anaconda3\envs\python10\lib\site-packages\datasets\load.py", line 1858, in dataset_module_factory
    raise DatasetNotFoundError(f"Dataset '{path}' doesn't exist on the Hub or cannot be accessed.") from e
datasets.exceptions.DatasetNotFoundError: Dataset 'opus' doesn't exist on the Hub or cannot be accessed.
